### 2020-08-01

-----
##### 1. 학습 날짜
- 2020-08-01

-----
##### 2. 학습 시간
- 08:00 ~ 20:00
-----
###### 3. 학습 범위 및 주제
- cpp module05

-----
##### 4. 동료 학습 방법
- slack

-----
##### 5. 학습 목표
- CPP module05 끝내기

-----
##### 6. 과제 제출
- https://github.com/simian114/CPP_PISCINE

-----
##### 7. 상세 학습 내용

### Module05

<details><summary>ex00</summary><blockquote>

<details><summary>구현 방향</summary><blockquote>
	
- 예외처리
  - [Exception Class](http://www.cplusplus.com/reference/exception/exception/)
  ```
  class exception {
  public:
    exception () throw();
    exception (const exception&) throw();
    exception& operator= (const exception&) throw();
    virtual ~exception() throw();
    virtual const char* what() const throw();
  }
  ```
- pdf를 보면 ***Bureaucrat::GradeTooHighException*** 과 같은 방식으로 예외처리를 호출하는거 같은데, 이렇게 되는거면 클래스 안에 예외처리 클래스를 만들어야 하는건가??
- 클래스안에 클래스를 만들면 생성할 때 어떻게 되는거지? 아래와 같은 코드로 예시를 들어보자.
  ```
  class base
  {
	  public:
		  base(void) { std::cout << "base!" << std::endl; }
	  class In
	  {
		  public:
		  	In(void) {std::cout << "In!" << std::endl;}
	  };
  };
  
  int main(void)
  {
    base a
  }
  ```
- 위의 실행 결과 base 객체만 생성된 걸 알 확인 할 수 있다! 
- In 클래스의 객체를 생성하기 위해서는 아래와 같은 방법을 따라야한다.
  ```
  base::In instance;
  ```
- 다시 본론으로 넘어와서 어떻게 예외처리 클래스를 만들까? 아래의 블로그에서는 정말 자신만의 예외처리 클래스를 만든다. 하지만 다른 깃허브를 본 결과 맨위 링크에 걸어놓은 ***exception class*** 을 상속받고 구현하는 방법을 사용했다. 나도 이 방법으로 만들도록 하겠다. 일단 이 방법을 사용하려면 exception class에 대한 이해가 필요해 보인다. 알아보자.
 
 - Exception class
  - 프라이빗 멤버 변수는 없다. 모든 멤버함수에 throw() 가 명시된걸로 보아서 모든 멤버함수에서 예외처리를 사용하는 걸로 확인된다.
  - virtual로 선언된 멤버함수는 아래 두개. 
    - virtual ~exception() throw()
    - virtual const char* what() const throw();
  - 소멸자는 익숙하므로 생략하고 ***what()*** 은 대체 뭐지?
    - what() 은 오류 메시지를 리턴해주는 함수로 이해하면 된다.
    - [여기 참고](http://www.cplusplus.com/reference/exception/exception/what/)
      - 여기를 보면 클래스로 만들어서 ***exceptopn class***를 상속 받는게 아니라 ***구조체***를 만들고 구조체에서 클래스를 할당받네? 이렇게 하면 뭔가 이점이 있을거 같은데... 이렇게 하면 설마 클래스처럼 귀찮게 모든 생성자, 소멸자 등을 만들어주지 않아도 되는거 아닌가?ㅋㅋㅋ---> 아마 아닌듯?ㅋㅋ


- 일단 ex00은 아래와 같은 방법으로 구현하자.
	1. Bureaucrat의 기본적인 생성, 소멸자 등을 만들어 준다. 생성자는 인자로 name, grade를 받게 만들자.
	2. Bureaucrat 클래스 안에 GradeTooLowException, GradeTooHighException 클래스를 만들어 준다.
	3. 위의 예외 클래스를 만들때는 exception 클래스를 상속받고 만들자.
	4. 다시 생성자로 돌아가서 1보다 작거나 150보다 크면 예외처리를 하게 만든다.
	5. 이제 Bureaucrat 클래스에서 incGrade, decGrade 함수를 만들자.
	5. 처음에 만들때는 ``` void incGrade(int val)``` 처럼 만들었는데, 이러면 예외처리를 해야하는게 너무 많아진다.
	6. 정말 간단하게 그냥++, -- 로 하나하나 올라가고 내려가게 만들자. 이렇게하면 구현해야하는 예외처리가 엄청 줄어든다.
	7. 그리고 ++, --는 클래스의 오버라이딩으로 만들어보자.
	8. 마지막으로 << 구현하면 끝!

- throw문을 생성자에 만들고 main문에서 의도적으로 예외가 생기게 ```Bureaucrat A("sanam", 160)``` 만들었더니 컴파일 오류가 생긴다.
- 이유는 throw로 예외를 내보냈는데 이를 받아줄 catch가 없기 때문에 생긴것!
- 그러면 도대체 어떻게 만들어야 하지? throw를 사용하는 함수에서 catch 문 까지 작성을 해야하는게 옳은건가? 아니면 그냥 이렇게 만들고 main 문에서 catch를 해야하나? 흠...
	

</blockquote></details>
<details><summary> 생성자에 try catch문을 쓰는게 옳은건가? </summary><blockquote>

- 나는 생성할 때 생성 인자로 주어진 값이 옳지 않으면 생성의 단계에서 바로 오류를 출력해야 한다고 생각했다.
- 즉, main문에서 try, catch를 사용하는게 아니라 constructor 함수에 try catch를 써야한다고 생각한 것.
- 하지만 이렇게 하면 문제가 있는듯 싶다. 아래와 같은 main 문이 있다고 생각하자.
	```
	int main(void)
	{
		Bureaucrat \*A;
		A = new Bureaucrat("sanam", 200);
		delete A;
	}
	```
- try catch문을 생성자 안에다가 만들었다고 생각하자.
- 그렇다면 위의 코드는 ```new Bureaucrat```의 단계에서 예외가 발생한다.
- ***하지만 A객체는 할당이 된다. 과연 이게 우리가 의도한 바일까?***
- 솔직히 나는 아직 잘 모르겠다. 구글링을 한 결과 많은 사람들이 생성자 단계에서는 ***throw***만을 던지고 main에서 객체를 생성 할 때 try catch 문을 이용하는 것 같다. 따라서 나는 앞으로 이 방법으로 진행.
	```
	int main(void)
	{
		Bureaucrat \*A;
		try
		{
			A = new Bureaucrat("sanam", 200);
		}
		catch (std::exception& e)
		{
			std::cout << e.what();
		}
		//delete A; 옳지 않은 방법. A는 생성 자체가 안됐다.
	}
	```
- 흠.. 위의 방식으로 main에서 try, catch 문을 사용하게 될 경우 포인터 형식이 아닌 일반 변수로는 try catch로 선언하기가 힘들어진다.
- 왜냐하면 try catch 블록에 선언을 해버리면 그 밖의 블록에서는 선언 자체가 되어버리지 않는 변수가 되기 때문.
- 방법이 아예 없는건 아니다. 아래처럼 하면 될거같다.
	- try 위에 변수를 하나 선언하자. 이 변수는 디폴트 생성자로 생성된다.
	- 그리고 try catch 문에서 임시로 변수를 생성하자. 만약 실패한다면 아래에 있는 명령들은 모두 무시되고 바로 catch문으로 감.
	- catch문으로 이동하지 않았다면 문제가 없다는 것. 이제 try문에서 만들어준 변수를 try 밖에서 생성해준 변수로 넣어주자.
	```
	int main(void)
	{
		Bureaucrat A;
		try
		{
			Bureautrat B;
			A = B;
		}
		catch (std::exception& e)
		{
			std::cout << e.what();
		}
		std::cout << A;
	}
	```
</blockquote></details>
</blockquote></details>

<details><summary>ex01</summary><blockquote>
	
<details><summary>헤더 꼬임 현상?</summary><blockquote>

- 이 부분에 대한 문제는 훨씬 이전에 해결했어야 했는데 내가 너무 게을러서 지금한다. (아마 module04 - ex03에서 처음 겪었던 걸로 기억)
- ex01을 다 완성하고 main으로 test를 돌리면 이상하게 안된다. 오류 문구가 잔뜩 뜬다.. 도대체 왜 이럴까? 난 분명 잘했는데? 문제는 헤더 꼬임현상이다.
- ex01의 Form을 A라고 하고 Bureaucrat을 B라고 하자.
	- A는 ```Form::beSigned(const Bureaucrat&)```에서 B를 사용한다. 따라서 A.hpp에는 ```include B``` 가 들어간다.
	- B는 ```Bureaucrat::signForm(Form&)``` 에서 A를 사용한다. 따라서 b.hpp에는 ```include A```가 들어간다.
	- A와 B 모두 서로를 include 해줘버리면 서로가 서로를 계속 찾게 되면서 무한루프에 빠지게 된다.
	- 결국 요점은 하나의 헤더 파일에만 다른 헤더파일을 ```include``` 해주고 나머지 하나에는 ```class``` 선언만 해준다.
	- 그리고 ```.cpp``` 파일에서 필요한 헤더파일을 ```include``` 해주면 문제 해결!
- [아주 정리 쓰무쓰킹](https://jrabbit.tistory.com/35)

</blockquote></details>
<details><summary>함수 내에서 TRY & CATCH?!</summary><blockquote>

- ex00을 진행할 때 생성자 내에서 ```try catch```를 사용해야 할지 여부에 대해서 알아봤다.
- 결과적으로 생성의 판단 유무가 중요한 생성자는 ```throw```만을 던져주고 밖에서 ```try catch```가 되어야 한다고 결론지어졌다.
- 그렇다면 클래스의 멤버함수 내에서는 어떻게 해야할까? 멤버함수도 만약 예외가 발생하면 ```throw```를 던지고 함수의 밖에서 ```catch```를 해야할까? 아마 아닐거 같다.
- 솔직히 어떻게 표현해야할지 모르겠다. 일단 이 부분은 나중에 수정하도록 하자.

</blockquote></details>

<details><summary>멤버변수를 const로 선언?!</summary><blockquote>

- 이 주제도 아마 이전 모듈에서 다뤄야했었을거 같긴하다...
- 아래와 같은 클래스가 있다고 생각하자.
	```
	class Test
	{
		private:
			const int	\_test1;
			int 		\_test2
		public:
			Test(int) : \_test1(test1), \_test2(test2) {}
	}
	```
- 일단 생성자에서는 아무런 문제가 없다. 하지만 생성자에서 조금 다른 방법인 아래처럼 하면 바로 문제가 생긴다.
	```
	Test::Test(int test1, int test2)
	{
		\_test1 = test1;
		\_test2 = test2;
	}
	```
- 오류 메시지는 다음과 같다.
	```
	test.cpp:7:3: error: constructor for 'Test' must explicitly initialize the const member '_test1'
                Test(int test1, int test2)
                ^
	test.cpp:4:13: note: declared here
                const int       _test1;
                                ^
	test.cpp:9:11: error: cannot assign to non-static data member '_test1' with const-qualified type 'const int'
                        _test1 = test1;
                        ~~~~~~ ^
	test.cpp:4:13: note: non-static data member '_test1' declared const here
                const int       _test1;
	```
- Module01의 ex06의 기억을 되살려 보면 레퍼런스로 선언된 멤버변수는 ***선언과 동시에 초기화*** 가 됐어야했다.
- const 멤버변수 또한 마찬가지다! 선언과 동시에 초기화가 되지 않으면 얄짤 없이 저런 메시지가 등장한다.
- 그럼 여기서 끝? 이 아니다 이제 ***할당연산자와 copy생성자 부분으로 넘어가야한다.***
- 지금까지의 할당 연산자에서는 모든 멤버 변수를 1 : 1로 넘겨주는 방법을 택했었다.
- 이제는 이렇게 하면 안된다. 왜냐하면 const 변수가 존재하기 때문....(copy생성자는 할당연산자를 바로 이용하는 형식으로 했으므로 당연히 안된다.)
- 그럼 어떻게 하냐??
- 앞으로는 할당연산자에서는 const 멤버 변수는 제외시켜주자.
- 아 그리고 copy 생성자도 일반 생성자에서처럼 함수 명 옆에서 바로 인자를 초기화 시킬 수 있다!
	- 그러므로 할당 연산자는 초기화 시켜주는 부분에서 copy의 인자를 this로 넣어주자
</blockquote></details>

<details><summary>인자없는 생성자</summary><blockquote>
	
- 바로 위에서 서술했던 const 멤버 변수가 있는 경우 인자없는 생성자를 무조건 선언해줘야 한다.
	- 선언하지 않으면 얄짤없이 컴파일 에러 등장.
- 하지만 ***나는 인자없는 생성자는 필요 없단말이야!***
	- 생성자를 ```private```로 선언하자!
- 생성자를 ```private```로 선언하게 될 경우 ```Test A```처럼 인자를 선언하지 못한다!
	- 하지만 우리가 원하지 않는 상황은 최대한 배제하게 만들 수 있기 때문에 ```priavte```로 선언하는게 좋아 보인다.
- 종합해보면
	- 인자없는 생성자 필요없다.
	- const 멤버 변수는 인자없는 생성자가 필요하다
- 해결책은 간단하다.
	```
	인자없는 생성자를 만들자. 대신! 초기값을 쓸모없는 값을 넣어주도록 하자. 그리고 private 영역에 선언함으로써 사용자가 호출하지 못하도록하자.
	```
	
	
</blockquote></details>
</blockquote></details>

-----

##### 8. 오늘 학습 내용에 대한 개인적인 총평
- cpp module05를 했다. 지난 몇일동안 너무 피곤해서 집중을 못했었는데 오늘은 피곤하지 않았아서 집중을 잘 할수 있었다. 보람찬 하루다.

-----
##### 9. 다음 학습 계획
- CPP MODULE05 보너스 및 module06
